/*/test/message/events_unhandled_error_subclass.js:5
new Foo().emit('error', new Error());
                        ^
Error
    at Object.<anonymous> (/*/test/message/events_unhandled_error_subclass.js:5:25)
    at Module._compile (internal/modules/cjs/loader.js:*:*)
    at Object.Module._extensions..js (internal/modules/cjs/loader.js:*:*)
    at Module.load (internal/modules/cjs/loader.js:*:*)
    at Function.Module._load (internal/modules/cjs/loader.js:*:*)
    at ModuleWrap.<anonymous> (internal/modules/esm/translators.js:*:*)
    at ModuleJob.run (internal/modules/esm/module_job.js:*:*)
    at async Loader.import (internal/modules/esm/loader.js:*:*)
Emitted 'error' event on Foo instance at:
    at Object.<anonymous> (/*/test/message/events_unhandled_error_subclass.js:5:11)
    at Module._compile (internal/modules/cjs/loader.js:*:*)
    [... lines matching original stack trace ...]
    at async Loader.import (internal/modules/esm/loader.js:*:*)
